<mujoco model="INB0104">
  <compiler angle="radian" meshdir="franka_emika_panda/assets/"/>

  <option cone="elliptic" impratio="100" noslip_tolerance="0" viscosity="0.00002" integrator="implicitfast" noslip_iterations="3">
    <flag multiccd="enable"/>
  </option>

  <visual>
    <global azimuth="120" elevation="-20"/>
    <quality shadowsize="8192"/>
    <headlight ambient="0.3 0.3 0.3" diffuse="0.6 0.6 0.6" specular="0.1 0.1 0.1"/>
    <rgba haze="0.15 0.25 0.35 1"/>
  </visual>

  <statistic extent="1" center="0.3 0 0.4"/>

  <default>
    <default class="panda">
      <material shininess="0.25"/>
      <joint range="-2.8973 2.8973" armature="0.1" damping="1"/>
      <default class="finger">
        <joint type="slide" range="0 0.04"/>
      </default>
      <default class="visual">
        <geom type="mesh" contype="0" conaffinity="0" group="2"/>
      </default>
      <default class="collision">
        <geom type="mesh" group="3"/>
      </default>
    </default>
    <default class="d435i">
      <material specular="0" shininess="0.25"/>
      <default class="d435i_visual">
        <geom type="mesh" contype="0" conaffinity="0" group="2"/>
      </default>
      <default class="d435i_collision">
        <geom type="mesh" group="3"/>
      </default>
    </default>
  </default>

  <extension>
    <plugin plugin="mujoco.elasticity.cable"/>
  </extension>

  <custom>
    <text name="composite_a" data="rope_a"/>
    <text name="composite_b" data="rope_b"/>
    <text name="composite_c" data="rope_c"/>
  </custom>

  <asset>
    <texture type="2d" name="groundplane" builtin="checker" mark="edge" rgb1="0.2 0.3 0.4" rgb2="0.1 0.2 0.3" markrgb="0.8 0.8 0.8" width="50" height="50"/>
    <texture type="2d" name="table" file="textures/table.png"/>
    <texture type="2d" name="plywood" file="textures/plywood.png"/>
    <texture type="2d" name="brick_wall" file="textures/brick_wall.png"/>
    <texture type="2d" name="aluminium" file="textures/aluminium.png"/>
    <texture type="2d" name="room" file="textures/room.png"/>
    <texture type="2d" name="field" file="textures/field.png"/>
    <texture type="2d" name="strawberry_color" file="textures/strawberry.png"/>
    <material name="white" class="panda"/>
    <material name="off_white" class="panda" rgba="0.901961 0.921569 0.929412 1"/>
    <material name="black" class="panda" rgba="0.25 0.25 0.25 1"/>
    <material name="green" class="panda" rgba="0 1 0 1"/>
    <material name="light_blue" class="panda" rgba="0.039216 0.541176 0.780392 1"/>
    <material name="Black_Acrylic" class="d435i" rgba="0.07036 0.07036 0.07036 1"/>
    <material name="Cameras_Gray" class="d435i" rgba="0.296138 0.296138 0.296138 1"/>
    <material name="IR_Emitter_Lens" class="d435i" rgba="0.28744 0.665387 0.327778 1"/>
    <material name="IR_Lens" class="d435i" rgba="0.035601 0.035601 0.035601 1"/>
    <material name="IR_Rim" class="d435i" rgba="0.799102 0.806952 0.799103 1"/>
    <material name="Metal_Casing" class="d435i"/>
    <material name="RGB_Pupil" class="d435i" rgba="0.08714 0.002866 0.009346 1"/>
    <material name="groundplane" texture="groundplane" texuniform="true" reflectance="0.2"/>
    <material name="plywood" texture="plywood" specular="1" shininess="1"/>
    <material name="brick_wall" texture="brick_wall" texrepeat="2 2" specular="1" shininess="1"/>
    <material name="aluminium" texture="aluminium" texuniform="true" specular="1" shininess="1"/>
    <material name="room" texture="field" specular="1" shininess="1"/>
    <material name="field" texture="field" specular="1" shininess="1"/>
    <material name="strawberry_material" texture="strawberry_color" texuniform="true" specular="0.1" shininess="0.1" reflectance="0.5"/>
    <mesh name="link0_c" file="link0.stl"/>
    <mesh name="link1_c" file="link1.stl"/>
    <mesh name="link2_c" file="link2.stl"/>
    <mesh name="link3_c" file="link3.stl"/>
    <mesh name="link4_c" file="link4.stl"/>
    <mesh name="link5_c0" file="link5_collision_0.obj"/>
    <mesh name="link5_c1" file="link5_collision_1.obj"/>
    <mesh name="link5_c2" file="link5_collision_2.obj"/>
    <mesh name="link6_c" file="link6.stl"/>
    <mesh name="link7_c" file="link7.stl"/>
    <mesh name="camera_mount_c" file="camera_mount_collision.stl"/>
    <mesh name="hand_c" file="hand.stl"/>
    <mesh name="gripper_long" file="gripper_long.stl"/>
    <mesh name="link0_0" file="link0_0.obj"/>
    <mesh name="link0_1" file="link0_1.obj"/>
    <mesh name="link0_2" file="link0_2.obj"/>
    <mesh name="link0_3" file="link0_3.obj"/>
    <mesh name="link0_4" file="link0_4.obj"/>
    <mesh name="link0_5" file="link0_5.obj"/>
    <mesh name="link0_7" file="link0_7.obj"/>
    <mesh name="link0_8" file="link0_8.obj"/>
    <mesh name="link0_9" file="link0_9.obj"/>
    <mesh name="link0_10" file="link0_10.obj"/>
    <mesh name="link0_11" file="link0_11.obj"/>
    <mesh name="link1" file="link1.obj"/>
    <mesh name="link2" file="link2.obj"/>
    <mesh name="link3_0" file="link3_0.obj"/>
    <mesh name="link3_1" file="link3_1.obj"/>
    <mesh name="link3_2" file="link3_2.obj"/>
    <mesh name="link3_3" file="link3_3.obj"/>
    <mesh name="link4_0" file="link4_0.obj"/>
    <mesh name="link4_1" file="link4_1.obj"/>
    <mesh name="link4_2" file="link4_2.obj"/>
    <mesh name="link4_3" file="link4_3.obj"/>
    <mesh name="link5_0" file="link5_0.obj"/>
    <mesh name="link5_1" file="link5_1.obj"/>
    <mesh name="link5_2" file="link5_2.obj"/>
    <mesh name="link6_0" file="link6_0.obj"/>
    <mesh name="link6_1" file="link6_1.obj"/>
    <mesh name="link6_2" file="link6_2.obj"/>
    <mesh name="link6_3" file="link6_3.obj"/>
    <mesh name="link6_4" file="link6_4.obj"/>
    <mesh name="link6_5" file="link6_5.obj"/>
    <mesh name="link6_6" file="link6_6.obj"/>
    <mesh name="link6_7" file="link6_7.obj"/>
    <mesh name="link6_8" file="link6_8.obj"/>
    <mesh name="link6_9" file="link6_9.obj"/>
    <mesh name="link6_10" file="link6_10.obj"/>
    <mesh name="link6_11" file="link6_11.obj"/>
    <mesh name="link6_12" file="link6_12.obj"/>
    <mesh name="link6_13" file="link6_13.obj"/>
    <mesh name="link6_14" file="link6_14.obj"/>
    <mesh name="link6_15" file="link6_15.obj"/>
    <mesh name="link6_16" file="link6_16.obj"/>
    <mesh name="link7_0" file="link7_0.obj"/>
    <mesh name="link7_1" file="link7_1.obj"/>
    <mesh name="link7_2" file="link7_2.obj"/>
    <mesh name="link7_3" file="link7_3.obj"/>
    <mesh name="link7_4" file="link7_4.obj"/>
    <mesh name="link7_5" file="link7_5.obj"/>
    <mesh name="link7_6" file="link7_6.obj"/>
    <mesh name="link7_7" file="link7_7.obj"/>
    <mesh name="camera_mount" file="camera_mount_visual.stl"/>
    <mesh name="hand_0" file="hand_0.obj"/>
    <mesh name="hand_1" file="hand_1.obj"/>
    <mesh name="hand_2" file="hand_2.obj"/>
    <mesh name="hand_3" file="hand_3.obj"/>
    <mesh name="hand_4" file="hand_4.obj"/>
    <mesh name="finger_0" file="finger_0.obj"/>
    <mesh name="finger_1" file="finger_1.obj"/>
    <mesh name="d435i_0" file="d435i_0.obj"/>
    <mesh name="d435i_1" file="d435i_1.obj"/>
    <mesh name="d435i_2" file="d435i_2.obj"/>
    <mesh name="d435i_3" file="d435i_3.obj"/>
    <mesh name="d435i_4" file="d435i_4.obj"/>
    <mesh name="d435i_5" file="d435i_5.obj"/>
    <mesh name="d435i_6" file="d435i_6.obj"/>
    <mesh name="d435i_7" file="d435i_7.obj"/>
    <mesh name="d435i_8" file="d435i_8.obj"/>
    <mesh name="strawberry" file="strawberry_new.obj" scale="0.006 0.006 0.006"/>
    <mesh name="strawberry_collision" file="strawberry_collision.obj" scale="0.006 0.006 0.006"/>
  </asset>

  <worldbody>
    <geom name="floor" size="0 0 0.05" pos="0 0 -1.06" type="plane" rgba="0.556 0.522 0.461 1"/>
    <body name="link0" childclass="panda">
      <inertial pos="-0.041018 -0.00014 0.049974" quat="0.00630474 0.751245 0.00741774 0.659952" mass="0.629769" diaginertia="0.00430465 0.00387984 0.00313051"/>
      <geom class="visual" material="off_white" mesh="link0_0"/>
      <geom class="visual" material="black" mesh="link0_1"/>
      <geom class="visual" material="off_white" mesh="link0_2"/>
      <geom class="visual" material="black" mesh="link0_3"/>
      <geom class="visual" material="off_white" mesh="link0_4"/>
      <geom class="visual" material="black" mesh="link0_5"/>
      <geom class="visual" material="white" mesh="link0_7"/>
      <geom class="visual" material="white" mesh="link0_8"/>
      <geom class="visual" material="black" mesh="link0_9"/>
      <geom class="visual" material="off_white" mesh="link0_10"/>
      <geom class="visual" material="white" mesh="link0_11"/>
      <geom class="collision" mesh="link0_c"/>
      <body name="link1" pos="0 0 0.333">
        <inertial pos="0.003875 0.002081 -0.04762" quat="0.711549 0.00634377 -0.0131124 0.702485" mass="4.97068" diaginertia="0.707137 0.703435 0.00852456"/>
        <joint name="joint1" pos="0 0 0" axis="0 0 1"/>
        <geom class="visual" material="white" mesh="link1"/>
        <geom class="collision" mesh="link1_c"/>
        <site name="joint1" pos="0 0 0"/>
        <body name="link2" quat="0.707107 -0.707107 0 0">
          <inertial pos="-0.003141 -0.02872 0.003495" quat="-0.168175 0.828366 -0.122878 0.520027" mass="0.646926" diaginertia="0.0310326 0.0283001 0.00273425"/>
          <joint name="joint2" pos="0 0 0" axis="0 0 1" range="-1.7628 1.7628"/>
          <geom class="visual" material="white" mesh="link2"/>
          <geom class="collision" mesh="link2_c"/>
          <site name="joint2" pos="0 0 0"/>
          <body name="link3" pos="0 -0.316 0" quat="0.707107 0.707107 0 0">
            <inertial pos="0.027518 0.039252 -0.066502" quat="0.662769 -0.00678331 0.252053 0.705096" mass="3.2286" diaginertia="0.0415014 0.0414793 0.00124635"/>
            <joint name="joint3" pos="0 0 0" axis="0 0 1"/>
            <geom class="visual" material="white" mesh="link3_0"/>
            <geom class="visual" material="white" mesh="link3_1"/>
            <geom class="visual" material="white" mesh="link3_2"/>
            <geom class="visual" material="black" mesh="link3_3"/>
            <geom class="collision" mesh="link3_c"/>
            <site name="joint3" pos="0 0 0"/>
            <body name="link4" pos="0.0825 0 0" quat="0.707107 0.707107 0 0">
              <inertial pos="-0.05317 0.104419 0.027454" quat="0.65058 0.529822 -0.0962034 0.535518" mass="3.5879" diaginertia="0.0349596 0.0281483 0.0106201"/>
              <joint name="joint4" pos="0 0 0" axis="0 0 1" range="-3.0718 -0.0698"/>
              <geom class="visual" material="white" mesh="link4_0"/>
              <geom class="visual" material="white" mesh="link4_1"/>
              <geom class="visual" material="black" mesh="link4_2"/>
              <geom class="visual" material="white" mesh="link4_3"/>
              <geom class="collision" mesh="link4_c"/>
              <site name="joint4" pos="0 0 0"/>
              <body name="link5" pos="-0.0825 0.384 0" quat="0.707107 -0.707107 0 0">
                <inertial pos="-0.011953 0.041065 -0.038437" quat="0.987313 -0.0121954 0.0719187 -0.141037" mass="1.22595" diaginertia="0.0367625 0.0288531 0.00803437"/>
                <joint name="joint5" pos="0 0 0" axis="0 0 1"/>
                <geom class="visual" material="black" mesh="link5_0"/>
                <geom class="visual" material="white" mesh="link5_1"/>
                <geom class="visual" material="white" mesh="link5_2"/>
                <geom class="collision" mesh="link5_c0"/>
                <geom class="collision" mesh="link5_c1"/>
                <geom class="collision" mesh="link5_c2"/>
                <site name="joint5" pos="0 0 0"/>
                <body name="link6" quat="0.707107 0.707107 0 0">
                  <inertial pos="0.060149 -0.014117 -0.010517" quat="0.101075 0.59332 0.0287227 0.798079" mass="1.66656" diaginertia="0.00584276 0.00431037 0.00159787"/>
                  <joint name="joint6" pos="0 0 0" axis="0 0 1" range="-0.0175 3.7525"/>
                  <geom class="visual" material="off_white" mesh="link6_0"/>
                  <geom class="visual" material="white" mesh="link6_1"/>
                  <geom class="visual" material="black" mesh="link6_2"/>
                  <geom class="visual" material="white" mesh="link6_3"/>
                  <geom class="visual" material="white" mesh="link6_4"/>
                  <geom class="visual" material="white" mesh="link6_5"/>
                  <geom class="visual" material="white" mesh="link6_6"/>
                  <geom class="visual" material="light_blue" mesh="link6_7"/>
                  <geom class="visual" material="light_blue" mesh="link6_8"/>
                  <geom class="visual" material="black" mesh="link6_9"/>
                  <geom class="visual" material="black" mesh="link6_10"/>
                  <geom class="visual" material="white" mesh="link6_11"/>
                  <geom class="visual" material="green" mesh="link6_12"/>
                  <geom class="visual" material="white" mesh="link6_13"/>
                  <geom class="visual" material="black" mesh="link6_14"/>
                  <geom class="visual" material="black" mesh="link6_15"/>
                  <geom class="visual" material="white" mesh="link6_16"/>
                  <geom class="collision" mesh="link6_c"/>
                  <site name="joint6" pos="0 0 0"/>
                  <body name="link7" pos="0.088 0 0" quat="0.707107 0.707107 0 0">
                    <inertial pos="0.010517 -0.004252 0.061597" quat="0.992939 -0.0762041 0.0733595 -0.0537067" mass="0.735522" diaginertia="0.0127345 0.0101055 0.00451803"/>
                    <joint name="joint7" pos="0 0 0" axis="0 0 1"/>
                    <geom class="visual" material="white" mesh="link7_0"/>
                    <geom class="visual" material="black" mesh="link7_1"/>
                    <geom class="visual" material="black" mesh="link7_2"/>
                    <geom class="visual" material="black" mesh="link7_3"/>
                    <geom class="visual" material="black" mesh="link7_4"/>
                    <geom class="visual" material="black" mesh="link7_5"/>
                    <geom class="visual" material="black" mesh="link7_6"/>
                    <geom class="visual" material="white" mesh="link7_7"/>
                    <geom class="collision" mesh="link7_c"/>
                    <site name="joint7" pos="0 0 0"/>
                    <body name="camera_mount" pos="0 0 0.107">
                      <inertial pos="0 0 0" mass="0.5" diaginertia="0 0 0"/>
                      <geom class="visual" material="black" mesh="camera_mount"/>
                      <geom class="collision" mesh="camera_mount_c"/>
                      <body name="d435i_1" childclass="d435i" pos="-0.032 -0.09676 0.02599" quat="0.953717 -0.300706 0 0">
                        <geom class="d435i_visual" mass="0" material="IR_Lens" mesh="d435i_0"/>
                        <geom class="d435i_visual" mass="0" material="IR_Emitter_Lens" mesh="d435i_1"/>
                        <geom class="d435i_visual" mass="0" material="IR_Rim" mesh="d435i_2"/>
                        <geom class="d435i_visual" mass="0" material="IR_Lens" mesh="d435i_3"/>
                        <geom class="d435i_visual" mass="0" material="Cameras_Gray" mesh="d435i_4"/>
                        <geom class="d435i_visual" mass="0" material="Black_Acrylic" mesh="d435i_5"/>
                        <geom class="d435i_visual" mass="0" material="Black_Acrylic" mesh="d435i_6"/>
                        <geom class="d435i_visual" mass="0" material="RGB_Pupil" mesh="d435i_7"/>
                        <geom class="d435i_visual" mass="0.072" material="Metal_Casing" mesh="d435i_8"/>
                        <geom class="d435i_collision" size="0.00968864 0.0334784" pos="0.00145113 -0.000319327 -0.0135412" quat="0.029024 0.708312 0.0275527 0.704764" type="capsule" mass="0"/>
                        <site name="camera_1_site" pos="0.0325 0 -0.003" size="0.001" rgba="1 0 0 1"/>
                        <body name="wrist1" pos="0.0325 0 -0.003" quat="0 0 1 0">
                          <camera name="wrist1" pos="0 0 0" fovy="42"/>
                        </body>
                      </body>
                      <body name="d435i_2" childclass="d435i" pos="0.032 0.09676 0.02599" quat="-2.21311e-08 -6.97791e-09 0.300706 -0.953717">
                        <geom class="d435i_visual" mass="0" material="IR_Lens" mesh="d435i_0"/>
                        <geom class="d435i_visual" mass="0" material="IR_Emitter_Lens" mesh="d435i_1"/>
                        <geom class="d435i_visual" mass="0" material="IR_Rim" mesh="d435i_2"/>
                        <geom class="d435i_visual" mass="0" material="IR_Lens" mesh="d435i_3"/>
                        <geom class="d435i_visual" mass="0" material="Cameras_Gray" mesh="d435i_4"/>
                        <geom class="d435i_visual" mass="0" material="Black_Acrylic" mesh="d435i_5"/>
                        <geom class="d435i_visual" mass="0" material="Black_Acrylic" mesh="d435i_6"/>
                        <geom class="d435i_visual" mass="0" material="RGB_Pupil" mesh="d435i_7"/>
                        <geom class="d435i_visual" mass="0.072" material="Metal_Casing" mesh="d435i_8"/>
                        <geom class="d435i_collision" size="0.00968864 0.0334784" pos="0.00145113 -0.000319327 -0.0135412" quat="0.029024 0.708312 0.0275527 0.704764" type="capsule" mass="0"/>
                        <site name="camera_2_site" pos="0.0325 0 -0.003" quat="0 0 1 0" size="0.001" rgba="1 0 0 1"/>
                        <body name="wrist2" pos="0.0325 0 -0.003" quat="0 0 1 0">
                          <camera name="wrist2" pos="0 0 0" fovy="42"/>
                        </body>
                      </body>
                      <body name="hand" pos="0 0 0.0016" quat="0.92388 0 0 -0.382683">
                        <inertial pos="-0.01 0 0.03" mass="0.73" diaginertia="0.001 0.0025 0.0017"/>
                        <geom class="visual" material="off_white" mesh="hand_0"/>
                        <geom class="visual" material="black" mesh="hand_1"/>
                        <geom class="visual" material="black" mesh="hand_2"/>
                        <geom class="visual" material="white" mesh="hand_3"/>
                        <geom class="visual" material="off_white" mesh="hand_4"/>
                        <geom class="collision" mesh="hand_c"/>
                        <site name="attachment_site" pos="0 0 0" quat="0 0 0 1"/>
                        <body name="pinch" pos="0 0 0.15">
                          <site name="pinch" pos="0 0 0" size="0.01" group="3" rgba="1 0 0 1"/>
                        </body>
                        <body name="left_finger" pos="0 0 0.0584">
                          <inertial pos="0 0 0" mass="0.015" diaginertia="2.375e-06 2.375e-06 7.5e-07"/>
                          <joint name="finger_joint1" class="finger" pos="0 0 0" axis="0 1 0"/>
                          <geom class="visual" material="off_white" mesh="finger_0"/>
                          <geom class="collision" mesh="finger_0"/>
                          <geom class="collision" friction="0.8 0.02 0.01" solimp="0.015 1 0.031" mesh="gripper_long"/>
                          <geom class="visual" material="black" mesh="gripper_long"/>
                        </body>
                        <body name="right_finger" pos="0 0 0.0584" quat="0 0 0 1">
                          <inertial pos="0 0 0" mass="0.015" diaginertia="2.375e-06 2.375e-06 7.5e-07"/>
                          <joint name="finger_joint2" class="finger" pos="0 0 0" axis="0 1 0"/>
                          <geom class="visual" material="off_white" mesh="finger_0"/>
                          <geom class="collision" mesh="finger_0"/>
                          <geom class="collision" friction="0.8 0.02 0.01" solimp="0.015 1 0.031" mesh="gripper_long"/>
                          <geom class="visual" material="black" mesh="gripper_long"/>
                        </body>
                      </body>
                    </body>
                  </body>
                </body>
              </body>
            </body>
          </body>
        </body>
      </body>
    </body>
    <body name="light0" pos="0.3 0 1.6">
      <site name="light0" pos="0 0 0" size="0.02" rgba="1 1 1 1"/>
      <light pos="0 0 0" dir="0 0 -1" ambient="0.1 0.1 0.1" diffuse="0.1 0.1 0.1"/>
    </body>
    <body name="roof_right" pos="0.3 0.09 1.5">
      <geom name="roof_right" size="0.25 0.52 0.004" type="box" material="plywood"/>
    </body>
    <body name="roof_left" pos="0.3 -0.96 1.5">
      <geom name="roof_left" size="0.35 0.52 0.004" type="box" material="plywood"/>
    </body>
    <body name="back_wall" pos="-0.5 0 0.5" quat="0.500398 0.499602 0.5 0.5">
      <geom name="back_wall" size="1.75 1.5 0.02" type="plane" material="brick_wall"/>
    </body>
    <body name="room" pos="2 0 0.5" quat="0.500398 0.499602 -0.5 -0.5">
      <geom name="room" size="1.75 1.5 0.02" type="plane" contype="0" conaffinity="0" material="room"/>
    </body>
    <body name="left_side_wall" pos="1.2 -1.54 0.5" quat="-2.59838e-06 2.59631e-06 0.706825 0.707388">
      <geom name="left_side_wall" size="1.75 1.5 0.02" type="plane" material="brick_wall"/>
    </body>
    <body name="right_side_wall" pos="1.2 1.54 0.5" quat="0.707388 0.706825 0 0">
      <geom name="right_side_wall" size="1.75 1.5 0.02" type="plane" material="brick_wall"/>
    </body>
    <body pos="-0.185 -0.43 -1.06">
      <geom name="back_left_leg" size="0.02 0.02 0.5" pos="0 -1 0.5" type="box" material="aluminium"/>
      <geom name="front_left_leg" size="0.02 0.02 0.5" pos="1 -1 0.5" type="box" material="aluminium"/>
      <geom name="back_left_pillar" size="0.02 0.02 0.75" pos="0 -1 1.79" type="box" material="aluminium"/>
      <geom name="front_left_pillar" size="0.02 0.02 0.746" pos="1 -1 1.794" type="box" material="aluminium"/>
      <geom name="back_right_leg" size="0.02 0.02 0.5" pos="0 1 0.5" type="box" material="aluminium"/>
      <geom name="front_right_leg" size="0.02 0.02 0.5" pos="1 1 0.5" type="box" material="aluminium"/>
      <geom name="back_right_pillar" size="0.02 0.02 0.75" pos="0 1 1.79" type="box" material="aluminium"/>
      <geom name="front_right_pillar" size="0.02 0.02 0.746" pos="1 1 1.794" type="box" material="aluminium"/>
      <geom name="front_middle_leg" size="0.02 0.02 0.5" pos="1 0 0.5" type="box" material="aluminium"/>
      <geom name="black_cover" size="0.16 0.218 0.001" pos="0.14 0.802 1.04" type="box" rgba="0.2 0.2 0.2 1"/>
      <geom name="x_bar_bottom_left" size="0.48 0.02 0.02" pos="0.5 -1 1.02" type="box" material="aluminium"/>
      <geom name="x_bar_top_left" size="0.48 0.02 0.02" pos="0.5 -1 2.52" type="box" material="aluminium"/>
      <geom name="x_bar_bottom_right" size="0.48 0.02 0.02" pos="0.5 1 1.02" type="box" material="aluminium"/>
      <geom name="x_bar_top_right" size="0.48 0.02 0.02" pos="0.5 1 2.52" type="box" material="aluminium"/>
      <geom name="x_bar_top_middle" size="0.48 0.02 0.02" pos="0.5 0 2.52" type="box" material="aluminium"/>
      <geom name="y_bar_bottom_front" size="0.02 1.02 0.02" pos="0 0 1.02" type="box" material="aluminium"/>
      <geom name="y_bar_top_front" size="0.02 0.98 0.02" pos="0 0 2.52" type="box" material="aluminium"/>
      <geom name="y_bar_bottom_back" size="0.02 1.02 0.02" pos="1 0 1.02" type="box" material="aluminium"/>
      <geom name="y_bar_top_back" size="0.02 0.98 0.02" pos="1 0 2.52" type="box" material="aluminium"/>
      <geom name="y_bar_robot_support" size="0.02 0.98 0.02" pos="0.28 0 1.02" type="box" material="aluminium"/>
      <geom name="y_bar_surface_support" size="0.02 0.98 0.02" pos="0.37 0 1.02" type="box" material="aluminium"/>
      <geom name="robot_base_plate" size="0.16 0.15 0.01" pos="0.14 0.43 1.05" type="box" material="aluminium"/>
      <geom name="right_tabletop" size="0.359 0.48 0.004" pos="0.661 0.54 1.044" quat="1.32679e-06 0 0 1" type="box" material="plywood"/>
      <geom name="left_tabletop" size="0.359 0.538 0.004" pos="0.661 -0.482 1.044" quat="1.32679e-06 0 0 1" type="box" material="plywood"/>
      <site name="origin" pos="0 0 0" size="0.01" rgba="1 0 0 1"/>
    </body>
    <body name="front" pos="1.6 0 0.6" quat="0.536456 0.460733 0.4611 0.536029">
      <camera name="front" pos="0 0 0" fovy="41"/>
    </body>
    <body name="target" pos="0.15 0 0.5" quat="0 1 0 0" mocap="true">
      <geom name="target" size="0.03 0.03 0.03" type="box" contype="0" conaffinity="0" rgba="0.6 0.3 0.3 0"/>
    </body>
    <body name="vine" pos="0.76 0 0.85" quat="0.707388 0 0.706825 0">
      <geom size="0.012 0.012 0.012" type="box" contype="0" conaffinity="0"/>
      <body name="aB_first">
        <joint name="aJ_first" pos="0 0 0" type="ball" group="3" actuatorfrclimited="false" damping="0.01"/>
        <geom name="aG0" size="0.0015 0.0375" pos="0.0375 0 0" quat="0.707107 0 -0.707107 0" type="capsule" rgba="0.208 0.337 0.149 1"/>
        <site name="aS_first" pos="0 0 0" group="3"/>
        <body name="aB_1" pos="0.075 0 0">
          <joint name="aJ_1" pos="0 0 0" type="ball" group="3" actuatorfrclimited="false" damping="0.01"/>
          <geom name="aG1" size="0.0015 0.0375" pos="0.0375 0 0" quat="0.707107 0 -0.707107 0" type="capsule" rgba="0.208 0.337 0.149 1"/>
          <body name="aB_2" pos="0.075 0 0">
            <joint name="aJ_2" pos="0 0 0" type="ball" group="3" actuatorfrclimited="false" damping="0.01"/>
            <geom name="aG2" size="0.0015 0.0375" pos="0.0375 0 0" quat="0.707107 0 -0.707107 0" type="capsule" rgba="0.208 0.337 0.149 1"/>
            <body name="aB_last" pos="0.075 0 0">
              <joint name="aJ_last" pos="0 0 0" type="ball" group="3" actuatorfrclimited="false" damping="0.01"/>
              <geom name="aG3" size="0.0015 0.0375" pos="0.0375 0 0" quat="0.707107 0 -0.707107 0" type="capsule" rgba="0.208 0.337 0.149 1"/>
              <site name="aS_last" pos="0.075 0 0" group="3"/>
              <body name="block" pos="0.15 0 0" quat="0.707388 0 0 0.706825">
                <geom name="block" type="mesh" group="3" friction="2" density="800" mesh="strawberry_collision"/>
                <geom name="block_visual" type="mesh" contype="0" conaffinity="0" material="strawberry_material" rgba="0.9 0.9 0.9 1" mesh="strawberry"/>
                <geom name="stem" type="capsule" size="0.0015 0.02" pos="0.0 0.056 0.0" euler="-1.57 0.0 0.0" rgba="0.208 0.337 0.149 1" friction="2"/>
                <site name="block_center" pos="0 0.02 0" size="0.01" group="3" rgba="0 1 0 1"/>
                <site name="stem" pos="0.005 0.062 -0.0005" size="0.0012" group="3" rgba="0 0 1 1"/>
                <site name="stem_grasp" pos="0.0021 0.049 -0.0005" size="0.0012" group="3" rgba="0 0 1 1"/>
              </body>
            </body>
          </body>
        </body>
      </body>
    </body>
    <body name="vine2" pos="0.72 0.04 0.85" quat="0.707388 0 0.706825 0">
      <geom size="0.012 0.012 0.012" type="box" contype="0" conaffinity="0"/>
      <body name="bB_first">
        <joint name="bJ_first" pos="0 0 0" type="ball" group="3" actuatorfrclimited="false" damping="0.01"/>
        <geom name="bG0" size="0.0015 0.0375" pos="0.0375 0 0" quat="0.707107 0 -0.707107 0" type="capsule" rgba="0.208 0.337 0.149 1"/>
        <site name="bS_first" pos="0 0 0" group="3"/>
        <body name="bB_1" pos="0.075 0 0">
          <joint name="bJ_1" pos="0 0 0" type="ball" group="3" actuatorfrclimited="false" damping="0.01"/>
          <geom name="bG1" size="0.0015 0.0375" pos="0.0375 0 0" quat="0.707107 0 -0.707107 0" type="capsule" rgba="0.208 0.337 0.149 1"/>
          <body name="bB_2" pos="0.075 0 0">
            <joint name="bJ_2" pos="0 0 0" type="ball" group="3" actuatorfrclimited="false" damping="0.01"/>
            <geom name="bG2" size="0.0015 0.0375" pos="0.0375 0 0" quat="0.707107 0 -0.707107 0" type="capsule" rgba="0.208 0.337 0.149 1"/>
            <body name="bB_last" pos="0.075 0 0">
              <joint name="bJ_last" pos="0 0 0" type="ball" group="3" actuatorfrclimited="false" damping="0.01"/>
              <geom name="bG3" size="0.0015 0.0375" pos="0.0375 0 0" quat="0.707107 0 -0.707107 0" type="capsule" rgba="0.208 0.337 0.149 1"/>
              <site name="bS_last" pos="0.075 0 0" group="3"/>
              <body name="block2" pos="0.1 0 0" quat="0.707388 0 0 0.706825">
                <geom name="block2" type="mesh" group="3" friction="0.9 0.5 1.2" density="800" mesh="strawberry_collision"/>
                <geom name="block2_visual" type="mesh" contype="0" conaffinity="0" rgba="0.1 0.6 0.1 1" mesh="strawberry"/>
                <geom name="stem2" type="capsule" size="0.0015 0.014" pos="0.0 0.05 0.0" euler="-1.57 0.0 0.0" rgba="0.208 0.337 0.149 1" friction="2 0.005 0.0001"/>
                <site name="stem2" pos="0.005 0.062 -0.0005" size="0.0012" group="3" rgba="0 0 1 1"/>
              </body>
            </body>
          </body>
        </body>
      </body>
    </body>
    <body name="vine3" pos="0.7 -0.03 0.85" quat="0.707388 0 0.706825 0">
      <geom size="0.012 0.012 0.012" type="box" contype="0" conaffinity="0"/>
      <body name="cB_first">
        <joint name="cJ_first" pos="0 0 0" type="ball" group="3" actuatorfrclimited="false" damping="0.01"/>
        <geom name="cG0" size="0.0015 0.0375" pos="0.0375 0 0" quat="0.707107 0 -0.707107 0" type="capsule" rgba="0.208 0.337 0.149 1"/>
        <site name="cS_first" pos="0 0 0" group="3"/>
        <body name="cB_1" pos="0.075 0 0">
          <joint name="cJ_1" pos="0 0 0" type="ball" group="3" actuatorfrclimited="false" damping="0.01"/>
          <geom name="cG1" size="0.0015 0.0375" pos="0.0375 0 0" quat="0.707107 0 -0.707107 0" type="capsule" rgba="0.208 0.337 0.149 1"/>
          <body name="cB_2" pos="0.075 0 0">
            <joint name="cJ_2" pos="0 0 0" type="ball" group="3" actuatorfrclimited="false" damping="0.01"/>
            <geom name="cG2" size="0.0015 0.0375" pos="0.0375 0 0" quat="0.707107 0 -0.707107 0" type="capsule" rgba="0.208 0.337 0.149 1"/>
            <body name="cB_last" pos="0.075 0 0">
              <joint name="cJ_last" pos="0 0 0" type="ball" group="3" actuatorfrclimited="false" damping="0.01"/>
              <geom name="cG3" size="0.0015 0.0375" pos="0.0375 0 0" quat="0.707107 0 -0.707107 0" type="capsule" rgba="0.208 0.337 0.149 1"/>
              <site name="cS_last" pos="0.075 0 0" group="3"/>
              <body name="block3" pos="0.1 0 0" quat="0.707388 0 0 0.706825">
                <geom name="block3" type="mesh" group="3" friction="0.9 0.5 1.2" density="800" mesh="strawberry_collision"/>
                <geom name="block3_visual" type="mesh" contype="0" conaffinity="0" rgba="0.1 0.6 0.1 1" mesh="strawberry"/>
                <geom name="stem3" type="capsule" size="0.0015 0.014" pos="0.0 0.05 0.0" euler="-1.57 0.0 0.0" rgba="0.208 0.337 0.149 1" friction="2 0.005 0.0001"/>
                <site name="stem3" pos="0.005 0.062 -0.0005" size="0.0012" group="3" rgba="0 0 1 1"/>
              </body>
            </body>
          </body>
        </body>
      </body>
    </body>
  </worldbody>

  <contact>
    <exclude body1="aB_first" body2="aB_1"/>
    <exclude body1="aB_1" body2="aB_2"/>
    <exclude body1="aB_2" body2="aB_last"/>
    <exclude body1="bB_first" body2="bB_1"/>
    <exclude body1="bB_1" body2="bB_2"/>
    <exclude body1="bB_2" body2="bB_last"/>
    <exclude body1="cB_first" body2="cB_1"/>
    <exclude body1="cB_1" body2="cB_2"/>
    <exclude body1="cB_2" body2="cB_last"/>
  </contact>

  <equality>
    <joint joint1="finger_joint1" joint2="finger_joint2" polycoef="0 1 0 0 0" solref="0.005" solimp="0.95 0.99"/>
    <weld name="strawb_joint" site1="aS_last" site2="stem" torquescale="8" solref="0.01"/>
    <weld name="strawb2_joint" site1="bS_last" site2="stem2" torquescale="8" solref="0.01"/>
    <weld name="strawb3_joint" site1="cS_last" site2="stem3" torquescale="8" solref="0.01"/>
  </equality>

  <tendon>
    <fixed name="split">
      <joint joint="finger_joint1" coef="0.5"/>
      <joint joint="finger_joint2" coef="0.5"/>
    </fixed>
  </tendon>

  <actuator>
    <general name="actuator1" class="panda" joint="joint1" forcerange="-87 87"/>
    <general name="actuator2" class="panda" joint="joint2" forcerange="-87 87"/>
    <general name="actuator3" class="panda" joint="joint3" forcerange="-87 87"/>
    <general name="actuator4" class="panda" joint="joint4" forcerange="-87 87"/>
    <general name="actuator5" class="panda" joint="joint5" forcerange="-12 12"/>
    <general name="actuator6" class="panda" joint="joint6" forcerange="-12 12"/>
    <general name="actuator7" class="panda" joint="joint7" forcerange="-12 12"/>
    <general name="fingers_actuator" class="panda" tendon="split" ctrlrange="0 255" forcerange="-100 100" biastype="affine" gainprm="0.0156863" biasprm="0 -100 -10"/>
  </actuator>

  <sensor>
    <jointpos joint="joint1" name="panda/joint1_pos"/>
    <jointpos joint="joint2" name="panda/joint2_pos"/>
    <jointpos joint="joint3" name="panda/joint3_pos"/>
    <jointpos joint="joint4" name="panda/joint4_pos"/>
    <jointpos joint="joint5" name="panda/joint5_pos"/>
    <jointpos joint="joint6" name="panda/joint6_pos"/>
    <jointpos joint="joint7" name="panda/joint7_pos"/>
    <jointvel joint="joint1" name="panda/joint1_vel"/>
    <jointvel joint="joint2" name="panda/joint2_vel"/>
    <jointvel joint="joint3" name="panda/joint3_vel"/>
    <jointvel joint="joint4" name="panda/joint4_vel"/>
    <jointvel joint="joint5" name="panda/joint5_vel"/>
    <jointvel joint="joint6" name="panda/joint6_vel"/>
    <jointvel joint="joint7" name="panda/joint7_vel"/>
    <torque site="joint1" name="panda/joint1_torque"/>
    <torque site="joint2" name="panda/joint2_torque"/>
    <torque site="joint3" name="panda/joint3_torque"/>
    <torque site="joint4" name="panda/joint4_torque"/>
    <torque site="joint5" name="panda/joint5_torque"/>
    <torque site="joint6" name="panda/joint6_torque"/>
    <torque site="joint7" name="panda/joint7_torque"/>
    <force site="attachment_site" name="panda/wrist_force"/>
    <framepos objtype="site" objname="pinch" name="pinch_pos"/>
    <framequat objtype="site" objname="pinch" name="pinch_quat"/>
    <framelinvel objtype="site" objname="pinch" name="pinch_vel"/>
    <framepos objtype="site" objname="stem_grasp" name="block_pos"/>
    <framequat objtype="geom" objname="block" name="block_quat"/>
    <framepos objtype="body" objname="block2" name="block2_pos"/>
    <framepos objtype="body" objname="block3" name="block3_pos"/>
  </sensor>
</mujoco>
