<mujoco model="strawb_vine">
    <body name="vine" pos="0.45 0 1.0" quat="0.707388 0 0.706825 0">
      <body name="aB_first">
        <joint name="aJ_first" pos="0 0 0" type="ball" group="3" actuatorfrclimited="false" damping="0.005"/>
        <geom name="aG0" size="0.0007 0.025" pos="0.025 0 0" quat="0.707107 0 -0.707107 0" 
              type="capsule" rgba="0.208 0.337 0.149 1"
              solref="0.01 1" solimp="0.9 0.95 0.001" friction="1.0 0.5 0.1" mass="0.0005"/>
        <site name="aS_first" pos="0 0 0" group="3"/>
        <body name="aB_1" pos="0.05 0 0">
          <joint name="aJ_1" pos="0 0 0" type="ball" group="3" actuatorfrclimited="false" damping="0.005"/>
          <geom name="aG1" size="0.0007 0.025" pos="0.025 0 0" quat="0.707107 0 -0.707107 0" 
                type="capsule" rgba="0.208 0.337 0.149 1"
                solref="0.01 1" solimp="0.9 0.95 0.001" friction="1.0 0.5 0.1" mass="0.0005"/>   
          <body name="aB_2" pos="0.05 0 0">
            <joint name="aJ_2" pos="0 0 0" type="ball" group="3" actuatorfrclimited="false" damping="0.005"/>
            <geom name="aG2" size="0.0007 0.025" pos="0.025 0 0" quat="0.707107 0 -0.707107 0" 
                  type="capsule" rgba="0.208 0.337 0.149 1"
                  solref="0.01 1" solimp="0.9 0.95 0.001" friction="1.0 0.5 0.1" mass="0.0005"/>   
            <body name="aB_last" pos="0.05 0 0">
              <joint name="aJ_last" pos="0 0 0" type="ball" group="3" actuatorfrclimited="false" damping="0.005"/>
              <geom name="aG3" size="0.0007 0.025" pos="0.025 0 0" quat="0.707107 0 -0.707107 0" 
                    type="capsule" rgba="0.208 0.337 0.149 1"
                    solref="0.01 1" solimp="0.9 0.95 0.001" friction="1.0 0.5 0.1" mass="0.0005"/>
              <site name="aS_last" pos="0.05 0 0" group="3"/>      
              <body name="block" pos="0.112 -0.00024 0.00052" quat="0.707388 0 0 0.706825">
                <geom name="block" type="mesh" mesh="strawberry_2_collision" density="800" group="3"/>
                <geom name="block_visual" type="mesh" mesh="strawberry_2" material="strawberry_2_material" contype="0" conaffinity="0"/>
                <geom name="strawberry_2_leaves" type="mesh" mesh="strawberry_2_leaves" rgba="0.9 0.9 0.9 1.0" material="strawberry_2_leaves" contype="0" conaffinity="0"/>
                <geom name="stem" type="capsule" size="0.0007 0.014" pos="0.0002 0.049 -0.00055" euler="-1.57 0.0 0.0" rgba="0.208 0.337 0.149 1"/>
                <site name="stem" pos="0.0001 0.054 -0.0004" size="0.0012" rgba="0 0 1 1" group="3"/>
                <site name="stem_grasp" pos="0.0001 0.038 -0.0004" size="0.0012" rgba="0 0 1 1" group="3"/>
              </body>
            </body>
          </body>
        </body>
      </body>
    </body>

</mujoco>